<?xml version="1.0"?>
<robot name="hexapod" xmlns:xacro="http://wiki.ros.org/xacro">
  <xacro:include filename="$(find robot_description)/properties.urdf.xacro" />

  <!-- base_footprint -->
  <link name="base_footprint" />
  <joint name="base_footprint_joint" type="fixed"> 
    <parent link="base_footprint" />
    <child link="base_link" />
  </joint>

  <!-- base_link -->
  <link name="base_link">
    <visual>
      <origin xyz="0 0 0" />
      <geometry>
        <box size="0.300 0.200 0.050" />
      </geometry>
      <material name="frame" />
    </visual>
    <inertial>
      <mass value="0.600" />
      <origin xyz="0 0 0" />
      <inertia ixx="0.0021" iyy="0.0046" izz="0.0065"
               ixy="0" ixz="0" iyz="0" />
    </inertial>
  </link>

  <!-- legs -->
  <xacro:macro name="leg" params="index reflect xyz rpy">
    <!-- leg_X: fixed to base_link -->
    <!-- TODO for Gazebo add inertial if whole link gets ignored -->
    <link name="leg_${index}" />
    <joint name="base_link__leg_${index}" type="fixed"> 
      <parent link="base_link" />
      <child link="leg_${index}" />
      <origin xyz="${xyz}" rpy="${rpy}" />
    </joint>

    <!-- leg_Xa: shoulder  -->
    <link name="leg_${index}a">
      <visual>
        <origin xyz="0 ${leg_a_length/2*reflect} 0" />
        <geometry>
          <box size="0.05 ${leg_a_length} 0.03" />
        </geometry>
      </visual>
      <inertial>
        <mass value="0.100" />
        <origin xyz="0 ${leg_a_length/2*reflect} 0" />
        <inertia ixx="0.000028" iyy="0.000028" izz="0.000028"
                 ixy="0"        ixz="0"        iyz="0" />
      </inertial>
    </link>
    <joint name="leg_${index}_base__leg_${index}a" type="revolute">
      <axis xyz="0 0 1" />
      <xacro:if value="${reflect == 1}">
        <limit lower="${joint_a_limit_lower}" upper="${joint_a_limit_upper}"
            effort="${joint_effort}" velocity="${joint_velocity}" />
      </xacro:if>
      <xacro:unless value="${reflect == 1}">
        <limit lower="${-joint_a_limit_upper}" upper="${-joint_a_limit_lower}"
            effort="${joint_effort}" velocity="${joint_velocity}" />
      </xacro:unless>
      <parent link="leg_${index}" />
      <child link="leg_${index}a" />
      <dynamics friction="${joint_friction}" />
    </joint>
    <!-- leg_Xb: upper segment -->
    <link name="leg_${index}b">
      <visual>
        <origin xyz="0 ${leg_b_length/2*reflect} 0" />
        <geometry>
          <box size="0.03 ${leg_b_length} 0.03" />
        </geometry>
      </visual>
      <inertial>
        <mass value="0.100" />
        <origin xyz="0 ${leg_b_length/2*reflect} 0" />
        <inertia ixx="0.000195" iyy="0.000010" izz="0.000195"
                 ixy="0"        ixz="0"        iyz="0" />
      </inertial>
    </link>
    <joint name="leg_${index}a__leg_${index}b" type="revolute">
      <axis xyz="1 0 0" />
      <xacro:if value="${reflect == 1}">
        <limit lower="${joint_b_limit_lower}" upper="${joint_b_limit_upper}"
            effort="${joint_effort}" velocity="${joint_velocity}" />
      </xacro:if>
      <xacro:unless value="${reflect == 1}">
        <limit lower="${-joint_b_limit_upper}" upper="${-joint_b_limit_lower}"
            effort="${joint_effort}" velocity="${joint_velocity}" />
      </xacro:unless>
      <parent link="leg_${index}a" />
      <child link="leg_${index}b" />
      <origin xyz="0 ${leg_a_length*reflect} 0" />
      <dynamics friction="${joint_friction}" />
    </joint>
    <!-- leg_Xc: lower segment (with foot) -->
    <link name="leg_${index}c">
      <visual>
        <origin xyz="0 ${leg_c_length/2*reflect} 0" />
        <geometry>
          <box size="0.03 ${leg_c_length} 0.03" />
        </geometry>
      </visual>
      <visual>
        <origin xyz="0 ${leg_c_length*reflect} 0" />
        <geometry>
          <sphere radius="0.03" />
        </geometry>
        <material name="feet" />
      </visual>
      <collision>
        <origin xyz="0 ${leg_c_length*reflect} 0" />
        <geometry>
          <sphere radius="0.03" />
        </geometry>
        <contact_coefficients mu="0.7" />
      </collision>
      <inertial>
        <mass value="0.100" />
        <origin xyz="0 ${leg_c_length/2*reflect} 0" />
        <inertia ixx="0.000195" iyy="0.000010" izz="0.000195"
                 ixy="0"        ixz="0"        iyz="0" />
      </inertial>
    </link>
    <joint name="leg_${index}b__leg_${index}c" type="revolute">
      <axis xyz="1 0 0" />
      <xacro:if value="${reflect == 1}">
        <limit lower="${joint_c_limit_lower}" upper="${joint_c_limit_upper}"
            effort="${joint_effort}" velocity="${joint_velocity}" />
      </xacro:if>
      <xacro:unless value="${reflect == 1}">
        <limit lower="${-joint_c_limit_upper}" upper="${-joint_c_limit_lower}"
            effort="${joint_effort}" velocity="${joint_velocity}" />
      </xacro:unless>
      <parent link="leg_${index}b" />
      <child link="leg_${index}c" />
      <origin xyz="0 ${leg_b_length*reflect} 0" />
      <dynamics friction="${joint_friction}" />
    </joint>
  </xacro:macro>
  <!-- Instantiate the six legs -->
  <xacro:leg index="0" reflect="1"  xyz=" 0.15  0.10 0.0" rpy="0 0 -${leg_spreading_angle}" />
  <xacro:leg index="1" reflect="1"  xyz=" 0.00  0.15 0.0" rpy="0 0 0" />
  <xacro:leg index="2" reflect="1"  xyz="-0.15  0.10 0.0" rpy="0 0 ${leg_spreading_angle}" />
  <xacro:leg index="3" reflect="-1" xyz=" 0.15 -0.10 0.0" rpy="0 0 ${leg_spreading_angle}" />
  <xacro:leg index="4" reflect="-1" xyz=" 0.00 -0.15 0.0" rpy="0 0 0" />
  <xacro:leg index="5" reflect="-1" xyz="-0.15 -0.10 0.0" rpy="0 0 -${leg_spreading_angle}" />

  <!-- Sensors -->
  <link name="imu" />
  <joint name="base_link__imu" type="fixed"> 
    <parent link="base_link" />
    <child link="imu" />
    <!-- TODO set correct pose -->
    <origin xyz="0 0 0.05" />
  </joint>

  <!-- Gazebo (simulation only) -->
  <!-- docs: https://github.com/gazebosim/gz-sim/tree/main/src/systems -->
  <gazebo>
    <plugin
      filename="gz-sim-odometry-publisher-system"
      name="gz::sim::systems::OdometryPublisher">
      <odom_publish_frequency>50</odom_publish_frequency>
      <odom_topic>/model/hexapod/odometry</odom_topic>
      <odom_frame>world</odom_frame>
      <robot_base_frame>base_link</robot_base_frame>
    </plugin>
    <plugin
      filename="gz-sim-joint-state-publisher-system"
      name="gz::sim::systems::JointStatePublisher">
      <topic>/model/hexapod/joint_state</topic>
    </plugin>
    <!-- TODO doesn't work, no imu topic in Gazebo gets published -->
    <plugin
      filename="gz-sim-imu-system"
      name="gz::sim::systems::Imu">
    </plugin>
  </gazebo>
</robot>
